Workbook
Name dep_Animal_Science_and_Veterinary_Medicine_Faculty: OFFSET(Lists!$Y$2,0,0,COUNTA(Lists!$Y$2:$Y$200),1)
Name dep_Business_Studies_Faculty: OFFSET(Lists!$V$2,0,0,COUNTA(Lists!$V$2:$V$200),1)
Name dep_Engineering_Faculty: OFFSET(Lists!$Q$2,0,0,COUNTA(Lists!$Q$2:$Q$200),1)
Name dep_Faculty_of_Agriculture: OFFSET(Lists!$X$2,0,0,COUNTA(Lists!$X$2:$X$200),1)
Name dep_Faculty_of_Agriculture_Sheikh_Hasina_Agriculture_Institute: OFFSET(Lists!$Y$2,0,0,COUNTA(Lists!$Y$2:$Y$200),1)
Name dep_Humanities_Faculty_Faculty_of_Arts: OFFSET(Lists!$T$2,0,0,COUNTA(Lists!$T$2:$T$200),1)
Name dep_Law_Faculty: OFFSET(Lists!$W$2,0,0,COUNTA(Lists!$W$2:$W$200),1)
Name dep_Life_Science_Faculty: OFFSET(Lists!$S$2,0,0,COUNTA(Lists!$S$2:$S$200),1)
Name dep_Science_Faculty: OFFSET(Lists!$R$2,0,0,COUNTA(Lists!$R$2:$R$200),1)
Name dep_Social_Science_Faculty: OFFSET(Lists!$U$2,0,0,COUNTA(Lists!$U$2:$U$200),1)
Name dv_ConfigDepartment: OFFSET(Lists!$D$2,0,0,COUNTA(Lists!$D$2:$D$200),1)
Name dv_ConfigDepartmentByFaculty: OFFSET(Lists!$AA$2,0,0,COUNTA(Lists!$AA$2:$AA$21),1)
Name dv_ConfigSemester: OFFSET(Lists!$B$2,0,0,COUNTA(Lists!$B$2:$B$200),1)
Name dv_ConfigYear: OFFSET(Lists!$A$2,0,0,COUNTA(Lists!$A$2:$A$200),1)
Name dv_CreditType: OFFSET(Lists!$K$2,0,0,COUNTA(Lists!$K$2:$K$200),1)
Name dv_CreditValue: OFFSET(Credit_Rules!$A$2,0,0,COUNTA(Credit_Rules!$A$2:$A$1000),1)
Name dv_Day: OFFSET(Lists!$M$2,0,0,COUNTA(Lists!$M$2:$M$200),1)
Name dv_Department: OFFSET(Lists!$D$2,0,0,COUNTA(Lists!$D$2:$D$200),1)
Name dv_Designation: OFFSET(Lists!$E$2,0,0,COUNTA(Lists!$E$2:$E$200),1)
Name dv_Faculty: OFFSET(Lists!$C$2,0,0,COUNTA(Lists!$C$2:$C$200),1)
Name dv_RoomID: OFFSET(Rooms!$A$2,0,0,COUNTA(Rooms!$A$2:$A$1000),1)
Name dv_RoomType: OFFSET(Lists!$L$2,0,0,COUNTA(Lists!$L$2:$L$200),1)
Name dv_Semester: OFFSET(Lists!$H$2,0,0,COUNTA(Lists!$H$2:$H$200),1)
Name dv_TeacherAbbr: OFFSET(Teachers!$B$2,0,0,COUNTA(Teachers!$B$2:$B$1000),1)
Name dv_Time: OFFSET(Lists!$F$2,0,0,COUNTA(Lists!$F$2:$F$200),1)
Name dv_Year: OFFSET(Lists!$G$2,0,0,COUNTA(Lists!$G$2:$G$200),1)
Name dv_YearGroup: OFFSET(Lists!$J$2,0,0,COUNTA(Lists!$J$2:$J$200),1)
Name dv_YearSem: OFFSET(Year_Sem!$F$2,0,0,COUNTIF(Year_Sem!$F$2:$F$1000,"?*"),1)
Name dv_YearSemEntry: OFFSET(Lists!$I$2,0,0,COUNTA(Lists!$I$2:$I$200),1)
Name dv_YesNo: OFFSET(Lists!$N$2,0,0,COUNTA(Lists!$N$2:$N$200),1)
Name rng_Courses: OFFSET(Courses!$A$2,0,0,MAX(1,COUNTIF(Courses!$A:$A,"?*")),6)
Name rng_Credit_Rules: OFFSET(Credit_Rules!$A$2,0,0,MAX(1,COUNTIF(Credit_Rules!$A:$A,"?*")),4)
Name rng_Day_Preference: OFFSET(Day_Preference!$A$2,0,0,MAX(1,COUNTIF(Day_Preference!$A:$A,"?*")),4)
Name rng_Room_Preference: OFFSET(Room_Preference!$A$2,0,0,MAX(1,COUNTIF(Room_Preference!$A:$A,"?*")),3)
Name rng_Rooms: OFFSET(Rooms!$A$2,0,0,MAX(1,COUNTIF(Rooms!$A:$A,"?*")),3)
Name rng_Teacher_Unavailability: OFFSET(Teacher_Unavailability!$A$2,0,0,MAX(1,COUNTIF(Teacher_Unavailability!$A:$A,"?*")),4)
Name rng_Teachers: OFFSET(Teachers!$A$2,0,0,MAX(1,COUNTIF(Teachers!$A:$A,"?*")),4)
Name rng_Year_Sem: OFFSET(Year_Sem!$A$2,0,0,MAX(1,COUNTIF(Year_Sem!$A:$A,"?*")),5)

Sheet Summary
A1: Routine Workbook Summary
A3: Check | B3: Count | C3: Meaning / action
A4: Teacher records entered | B4: =COUNTIF(Teachers!$A$2:$A$1000,"?*") -> 11 | C4: =IF(B4=0,"No teacher records yet","OK") -> OK
A5: Course records entered | B5: =COUNTIF(Courses!$A$2:$A$1000,"?*") -> 43 | C5: =IF(B5=0,"No course records yet","OK") -> OK
A6: Room records entered | B6: =COUNTIF(Rooms!$A$2:$A$1000,"?*") -> 5 | C6: =IF(B6=0,"No room records yet","OK") -> OK
A7: Active Year-Semester records | B7: =COUNTIF(Year_Sem!$E$2:$E$1000,"Yes") -> 5 | C7: =IF(B7=0,"No active Year-Semester records","OK") -> OK
A8: Courses without teacher | B8: =COUNTIFS(Courses!$A$2:$A$1000,"?*",Courses!$F$2:$F$1000,"") -> 0 | C8: =IF(B8=0,"OK","Assign a teacher to each course") -> OK
A9: Room preference problems | B9: =COUNTIFS(Room_Preference!$D$2:$D$1000,"<>OK",Room_Preference!$A$2:$A$1000,"?*") -> 0 | C9: =IF(B9=0,"OK","Review red status cells in Room_Preference") -> OK
A10: Day preference problems | B10: =COUNTIFS(Day_Preference!$D$2:$D$500,"<>OK",Day_Preference!$A$2:$A$500,"?*") -> 0 | C10: =IF(B10=0,"OK","Review red status cells in Day_Preference") -> OK
A11: Teacher availability problems | B11: =COUNTIFS(Teacher_Unavailability!$E$2:$E$500,"<>OK",Teacher_Unavailability!$A$2:$A$500,"?*") -> 0 | C11: =IF(B11=0,"OK","Review red status cells in Teacher_Unavailability") -> OK
A14: Instructions
A15: Fill in this order: Lists → Config (Year → Semester) → Year_Sem → Teachers → Credit_Rules → Courses → Rooms → Room_Preference → Day_Preference → Teacher_Unavailability.
A18: Required-field key
A19: * Required field
A20: Yellow cell = required value missing
A21: Red status = duplicate, conflict, or invalid value
A23: Quick links
A24: Lists
A25: Config
A26: Year_Sem
A27: Teachers
A28: Credit_Rules
... A33: Teacher_Unavailability

Sheet Lists
A1: Config_Year | B1: Config_Semester | C1: Faculty | D1: Department_Full | E1: Designation | F1: Time | G1: Year | H1: Semester | I1: year_sem | J1: Year_Group | K1: Credit_Type | L1: Room_Type | M1: Day | N1: Yes_No | O1: Faculty_Dependent_Name | P1: Faculty_Dependent_Key | Q1: dep_Engineering_Faculty | R1: dep_Science_Faculty | S1: dep_Life_Science_Faculty | T1: dep_Humanities_Faculty | U1: dep_Social_Science_Faculty | V1: dep_Business_Studies_Faculty | W1: dep_Law_Faculty | X1: dep_Faculty_of_Agriculture | Y1: dep_Animal_Science_and_Veterinary_Medicine_Faculty | AA1: Selected_Faculty_Departments
A2: 2026 | B2: Fall | C2: Engineering Faculty | D2: CSE | E2: Professor | F2: 0.375 | G2: 1 | H2: 1 | I2: 1-1 | J2: 1-2 | K2: Theory | L2: classroom | M2: SUN | N2: Yes | O2: Engineering Faculty | P2: dep_Engineering_Faculty | Q2: CSE | R2: Physics | S2: Pharmacy | T2: English | U2: Psychology | V2: Management Studies | W2: Law | X2: Agriculture | Y2: ASVM | AA2: =IFERROR(INDEX(CHOOSE(MATCH(Config!$B$3,$O$2:$O$10,0),$Q$2:$Q$21,$R$2:$R$21,$S$2:$S$21,$T$2:$T$21,$U$2:$U$21,$V$2:$V$21,$W$2:$W$21,$X$2:$X$21,$Y$2:$Y$21),1),"") -> CSE
A3: 2027 | B3: Spring | C3: Science Faculty | D3: EEE | E3: Associate Professor | F3: 0.38194444 | G3: 2 | H3: 2 | I3: 1-2 | J3: 3-4 | K3: Lab | L3: lab | M3: MON | N3: No | O3: Science Faculty | P3: dep_Science_Faculty | Q3: EEE | R3: Chemistry | S3: BGE | T3: Bangla | U3: Economics | V3: AIS | X3: FMB | AA3: =IFERROR(INDEX(CHOOSE(MATCH(Config!$B$3,$O$2:$O$10,0),$Q$2:$Q$21,$R$2:$R$21,$S$2:$S$21,$T$2:$T$21,$U$2:$U$21,$V$2:$V$21,$W$2:$W$21,$X$2:$X$21,$Y$2:$Y$21),2),"") -> EEE
A4: 2028 | C4: Life Science Faculty | D4: ETE | E4: Assistant Professor | F4: 0.38888889 | G4: 3 | I4: 2-1 | M4: TUE | O4: Life Science Faculty | P4: dep_Life_Science_Faculty | Q4: ETE | R4: Mathematics | S4: BMB | T4: History | U4: Sociology | V4: Marketing | AA4: =IFERROR(INDEX(CHOOSE(MATCH(Config!$B$3,$O$2:$O$10,0),$Q$2:$Q$21,$R$2:$R$21,$S$2:$S$21,$T$2:$T$21,$U$2:$U$21,$V$2:$V$21,$W$2:$W$21,$X$2:$X$21,$Y$2:$Y$21),3),"") -> ETE
A5: 2029 | C5: Humanities Faculty | D5: ACCE | E5: Lecturer | F5: 0.39583333 | G5: 4 | I5: 2-2 | M5: WED | O5: Humanities Faculty | P5: dep_Humanities_Faculty | Q5: ACCE | R5: Statistics | S5: Botany | U5: PAD | V5: Finance and Banking | AA5: =IFERROR(INDEX(CHOOSE(MATCH(Config!$B$3,$O$2:$O$10,0),$Q$2:$Q$21,$R$2:$R$21,$S$2:$S$21,$T$2:$T$21,$U$2:$U$21,$V$2:$V$21,$W$2:$W$21,$X$2:$X$21,$Y$2:$Y$21),4),"") -> ACCE
C6: Social Science Faculty | D6: CE | F6: 0.40277778 | I6: 3-1 | M6: THU | O6: Social Science Faculty | P6: dep_Social_Science_Faculty | Q6: CE | R6: ESDM | U6: IR | V6: THM | AA6: =IFERROR(INDEX(CHOOSE(MATCH(Config!$B$3,$O$2:$O$10,0),$Q$2:$Q$21,$R$2:$R$21,$S$2:$S$21,$T$2:$T$21,$U$2:$U$21,$V$2:$V$21,$W$2:$W$21,$X$2:$X$21,$Y$2:$Y$21),5),"") -> CE
C7: Business Studies Faculty | D7: Food and Agroprocess Engineering | F7: 0.40972222 | I7: 3-2 | O7: Business Studies Faculty | P7: dep_Business_Studies_Faculty | Q7: Food and Agroprocess Engineering | U7: PS | AA7: =IFERROR(INDEX(CHOOSE(MATCH(Config!$B$3,$O$2:$O$10,0),$Q$2:$Q$21,$R$2:$R$21,$S$2:$S$21,$T$2:$T$21,$U$2:$U$21,$V$2:$V$21,$W$2:$W$21,$X$2:$X$21,$Y$2:$Y$21),6),"") -> Food and Agroprocess Engineering
C8: Law Faculty | D8: ARCH | F8: 0.41666667 | I8: 4-1 | O8: Law Faculty | P8: dep_Law_Faculty | Q8: ARCH | AA8: =IFERROR(INDEX(CHOOSE(MATCH(Config!$B$3,$O$2:$O$10,0),$Q$2:$Q$21,$R$2:$R$21,$S$2:$S$21,$T$2:$T$21,$U$2:$U$21,$V$2:$V$21,$W$2:$W$21,$X$2:$X$21,$Y$2:$Y$21),7),"") -> ARCH
C9: Faculty of Agriculture | D9: Physics | F9: 0.42361111 | I9: 4-2 | O9: Faculty of Agriculture | P9: dep_Faculty_of_Agriculture | AA9: =IFERROR(INDEX(CHOOSE(MATCH(Config!$B$3,$O$2:$O$10,0),$Q$2:$Q$21,$R$2:$R$21,$S$2:$S$21,$T$2:$T$21,$U$2:$U$21,$V$2:$V$21,$W$2:$W$21,$X$2:$X$21,$Y$2:$Y$21),8),"") -> 0
C10: Animal Science and Veterinary Medicine Faculty | D10: Chemistry | F10: 0.43055556 | O10: Animal Science and Veterinary Medicine Faculty | P10: dep_Animal_Science_and_Veterinary_Medicine_Faculty | AA10: =IFERROR(INDEX(CHOOSE(MATCH(Config!$B$3,$O$2:$O$10,0),$Q$2:$Q$21,$R$2:$R$21,$S$2:$S$21,$T$2:$T$21,$U$2:$U$21,$V$2:$V$21,$W$2:$W$21,$X$2:$X$21,$Y$2:$Y$21),9),"") -> 0
D11: Mathematics | F11: 0.4375 | AA11: =IFERROR(INDEX(CHOOSE(MATCH(Config!$B$3,$O$2:$O$10,0),$Q$2:$Q$21,$R$2:$R$21,$S$2:$S$21,$T$2:$T$21,$U$2:$U$21,$V$2:$V$21,$W$2:$W$21,$X$2:$X$21,$Y$2:$Y$21),10),"") -> 0
D12: Statistics | F12: 0.44444444 | AA12: =IFERROR(INDEX(CHOOSE(MATCH(Config!$B$3,$O$2:$O$10,0),$Q$2:$Q$21,$R$2:$R$21,$S$2:$S$21,$T$2:$T$21,$U$2:$U$21,$V$2:$V$21,$W$2:$W$21,$X$2:$X$21,$Y$2:$Y$21),11),"") -> 0
D13: ESDM | F13: 0.45138889 | AA13: =IFERROR(INDEX(CHOOSE(MATCH(Config!$B$3,$O$2:$O$10,0),$Q$2:$Q$21,$R$2:$R$21,$S$2:$S$21,$T$2:$T$21,$U$2:$U$21,$V$2:$V$21,$W$2:$W$21,$X$2:$X$21,$Y$2:$Y$21),12),"") -> 0
D14: Pharmacy | F14: 0.45833333 | AA14: =IFERROR(INDEX(CHOOSE(MATCH(Config!$B$3,$O$2:$O$10,0),$Q$2:$Q$21,$R$2:$R$21,$S$2:$S$21,$T$2:$T$21,$U$2:$U$21,$V$2:$V$21,$W$2:$W$21,$X$2:$X$21,$Y$2:$Y$21),13),"") -> 0
D15: BGE | F15: 0.46527778 | AA15: =IFERROR(INDEX(CHOOSE(MATCH(Config!$B$3,$O$2:$O$10,0),$Q$2:$Q$21,$R$2:$R$21,$S$2:$S$21,$T$2:$T$21,$U$2:$U$21,$V$2:$V$21,$W$2:$W$21,$X$2:$X$21,$Y$2:$Y$21),14),"") -> 0
D16: BMB | F16: 0.47222222 | AA16: =IFERROR(INDEX(CHOOSE(MATCH(Config!$B$3,$O$2:$O$10,0),$Q$2:$Q$21,$R$2:$R$21,$S$2:$S$21,$T$2:$T$21,$U$2:$U$21,$V$2:$V$21,$W$2:$W$21,$X$2:$X$21,$Y$2:$Y$21),15),"") -> 0
D17: Botany | F17: 0.47916667
D18: Psychology | F18: 0.48611111 | AA18: =IFERROR(INDEX(CHOOSE(MATCH(Config!$B$3,$O$2:$O$10,0),$Q$2:$Q$21,$R$2:$R$21,$S$2:$S$21,$T$2:$T$21,$U$2:$U$21,$V$2:$V$21,$W$2:$W$21,$X$2:$X$21,$Y$2:$Y$21),16),"") -> 0
D19: Management Studies | F19: 0.49305556 | AA19: =IFERROR(INDEX(CHOOSE(MATCH(Config!$B$3,$O$2:$O$10,0),$Q$2:$Q$21,$R$2:$R$21,$S$2:$S$21,$T$2:$T$21,$U$2:$U$21,$V$2:$V$21,$W$2:$W$21,$X$2:$X$21,$Y$2:$Y$21),17),"") -> 0
D20: AIS | F20: 0.5 | AA20: =IFERROR(INDEX(CHOOSE(MATCH(Config!$B$3,$O$2:$O$10,0),$Q$2:$Q$21,$R$2:$R$21,$S$2:$S$21,$T$2:$T$21,$U$2:$U$21,$V$2:$V$21,$W$2:$W$21,$X$2:$X$21,$Y$2:$Y$21),18),"") -> 0
D21: Marketing | F21: 0.50694444 | AA21: =IFERROR(INDEX(CHOOSE(MATCH(Config!$B$3,$O$2:$O$10,0),$Q$2:$Q$21,$R$2:$R$21,$S$2:$S$21,$T$2:$T$21,$U$2:$U$21,$V$2:$V$21,$W$2:$W$21,$X$2:$X$21,$Y$2:$Y$21),19),"") -> 0
D22: Finance and Banking | F22: 0.51388889 | AA22: =IFERROR(INDEX(CHOOSE(MATCH(Config!$B$3,$O$2:$O$10,0),$Q$2:$Q$21,$R$2:$R$21,$S$2:$S$21,$T$2:$T$21,$U$2:$U$21,$V$2:$V$21,$W$2:$W$21,$X$2:$X$21,$Y$2:$Y$21),20),"") -> 0
D23: THM | F23: 0.52083333
D24: Economics | F24: 0.52777778
D25: Sociology | F25: 0.53472222
D26: PAD | F26: 0.54166667
D27: IR | F27: 0.54861111
D28: PS | F28: 0.55555556
D29: English | F29: 0.5625
D30: Bangla | F30: 0.56944444
D31: History | F31: 0.57638889
D32: Agriculture | F32: 0.58333333
D33: FMB | F33: 0.59027778
D34: ASVM | F34: 0.59722222
D35: Law | F35: 0.60416667
F36: 0.61111111
F37: 0.61805556
F38: 0.625
F39: 0.63194444
F40: 0.63888889
...

Sheet Config
A1: key | B1: value | C1: status
A2: university | B2: Gopalganj Science and Technology University | C2: =IF(COUNTA($B$2:$B$11)<10,"REQUIRED CONFIG VALUE MISSING","OK") -> OK
A3: faculty | B3: Engineering Faculty
A4: department | B4: CSE
A5: year | B5: 2026
A6: semester | B6: Fall
A7: working_days | B7: SUN,MON,TUE,WED,THU
A8: class_start | B8: 0.375
A9: class_end | B9: 0.65972222
A10: break_start | B10: 0.54861111
A11: break_end | B11: 0.59027778

Sheet Year_Sem
A1: year_sem * | B1: year * | C1: semester * | D1: group_code * | E1: is_active * | F1: active_year_sem_helper | G1: active_sequence_helper | H1: status
A2: 1-1 | B2: 1 | C2: 1 | D2: 1-2 | E2: Yes | F2: =IFERROR(INDEX($A$2:$A$1000,MATCH(ROWS($F$2:F2),$G$2:$G$1000,0)),"") -> 1-1 | G2: =IF($E2="Yes",COUNTIF($E$2:$E2,"Yes"),"") -> 1 | H2: =IF(COUNTA(A2:E2)=0,"",IF(COUNTIF($A$2:$A$1000,A2)>1,"DUPLICATE YEAR_SEM",IF(OR(B2<1,B2>4,C2<1,C2>2),"INVALID YEAR/SEMESTER","OK"))) -> OK
A3: 1-2 | B3: 1 | C3: 2 | D3: 1-2 | E3: No | F3: =IFERROR(INDEX($A$2:$A$1000,MATCH(ROWS($F$2:F3),$G$2:$G$1000,0)),"") -> 2-1 | G3: =IF($E3="Yes",COUNTIF($E$2:$E3,"Yes"),"") | H3: =IF(COUNTA(A3:E3)=0,"",IF(COUNTIF($A$2:$A$1000,A3)>1,"DUPLICATE YEAR_SEM",IF(OR(B3<1,B3>4,C3<1,C3>2),"INVALID YEAR/SEMESTER","OK"))) -> OK
A4: 2-1 | B4: 2 | C4: 1 | D4: 1-2 | E4: Yes | F4: =IFERROR(INDEX($A$2:$A$1000,MATCH(ROWS($F$2:F4),$G$2:$G$1000,0)),"") -> 2-2 | G4: =IF($E4="Yes",COUNTIF($E$2:$E4,"Yes"),"") -> 2 | H4: =IF(COUNTA(A4:E4)=0,"",IF(COUNTIF($A$2:$A$1000,A4)>1,"DUPLICATE YEAR_SEM",IF(OR(B4<1,B4>4,C4<1,C4>2),"INVALID YEAR/SEMESTER","OK"))) -> OK
A5: 2-2 | B5: 2 | C5: 2 | D5: 1-2 | E5: Yes | F5: =IFERROR(INDEX($A$2:$A$1000,MATCH(ROWS($F$2:F5),$G$2:$G$1000,0)),"") -> 3-2 | G5: =IF($E5="Yes",COUNTIF($E$2:$E5,"Yes"),"") -> 3 | H5: =IF(COUNTA(A5:E5)=0,"",IF(COUNTIF($A$2:$A$1000,A5)>1,"DUPLICATE YEAR_SEM",IF(OR(B5<1,B5>4,C5<1,C5>2),"INVALID YEAR/SEMESTER","OK"))) -> OK
A6: 3-1 | B6: 3 | C6: 1 | D6: 3-4 | E6: No | F6: =IFERROR(INDEX($A$2:$A$1000,MATCH(ROWS($F$2:F6),$G$2:$G$1000,0)),"") -> 4-1 | G6: =IF($E6="Yes",COUNTIF($E$2:$E6,"Yes"),"") | H6: =IF(COUNTA(A6:E6)=0,"",IF(COUNTIF($A$2:$A$1000,A6)>1,"DUPLICATE YEAR_SEM",IF(OR(B6<1,B6>4,C6<1,C6>2),"INVALID YEAR/SEMESTER","OK"))) -> OK
A7: 3-2 | B7: 3 | C7: 2 | D7: 3-4 | E7: Yes | F7: =IFERROR(INDEX($A$2:$A$1000,MATCH(ROWS($F$2:F7),$G$2:$G$1000,0)),"") | G7: =IF($E7="Yes",COUNTIF($E$2:$E7,"Yes"),"") -> 4 | H7: =IF(COUNTA(A7:E7)=0,"",IF(COUNTIF($A$2:$A$1000,A7)>1,"DUPLICATE YEAR_SEM",IF(OR(B7<1,B7>4,C7<1,C7>2),"INVALID YEAR/SEMESTER","OK"))) -> OK
A8: 4-1 | B8: 4 | C8: 1 | D8: 3-4 | E8: Yes | F8: =IFERROR(INDEX($A$2:$A$1000,MATCH(ROWS($F$2:F8),$G$2:$G$1000,0)),"") | G8: =IF($E8="Yes",COUNTIF($E$2:$E8,"Yes"),"") -> 5 | H8: =IF(COUNTA(A8:E8)=0,"",IF(COUNTIF($A$2:$A$1000,A8)>1,"DUPLICATE YEAR_SEM",IF(OR(B8<1,B8>4,C8<1,C8>2),"INVALID YEAR/SEMESTER","OK"))) -> OK
A9: 4-2 | B9: 4 | C9: 2 | D9: 3-4 | E9: No | F9: =IFERROR(INDEX($A$2:$A$1000,MATCH(ROWS($F$2:F9),$G$2:$G$1000,0)),"") | G9: =IF($E9="Yes",COUNTIF($E$2:$E9,"Yes"),"") | H9: =IF(COUNTA(A9:E9)=0,"",IF(COUNTIF($A$2:$A$1000,A9)>1,"DUPLICATE YEAR_SEM",IF(OR(B9<1,B9>4,C9<1,C9>2),"INVALID YEAR/SEMESTER","OK"))) -> OK
F10: =IFERROR(INDEX($A$2:$A$1000,MATCH(ROWS($F$2:F10),$G$2:$G$1000,0)),"") | G10: =IF($E10="Yes",COUNTIF($E$2:$E10,"Yes"),"") | H10: =IF(COUNTA(A10:E10)=0,"",IF(COUNTIF($A$2:$A$1000,A10)>1,"DUPLICATE YEAR_SEM",IF(OR(B10<1,B10>4,C10<1,C10>2),"INVALID YEAR/SEMESTER","OK")))
F11: =IFERROR(INDEX($A$2:$A$1000,MATCH(ROWS($F$2:F11),$G$2:$G$1000,0)),"") | G11: =IF($E11="Yes",COUNTIF($E$2:$E11,"Yes"),"") | H11: =IF(COUNTA(A11:E11)=0,"",IF(COUNTIF($A$2:$A$1000,A11)>1,"DUPLICATE YEAR_SEM",IF(OR(B11<1,B11>4,C11<1,C11>2),"INVALID YEAR/SEMESTER","OK")))
F12: =IFERROR(INDEX($A$2:$A$1000,MATCH(ROWS($F$2:F12),$G$2:$G$1000,0)),"") | G12: =IF($E12="Yes",COUNTIF($E$2:$E12,"Yes"),"") | H12: =IF(COUNTA(A12:E12)=0,"",IF(COUNTIF($A$2:$A$1000,A12)>1,"DUPLICATE YEAR_SEM",IF(OR(B12<1,B12>4,C12<1,C12>2),"INVALID YEAR/SEMESTER","OK")))
F13: =IFERROR(INDEX($A$2:$A$1000,MATCH(ROWS($F$2:F13),$G$2:$G$1000,0)),"") | G13: =IF($E13="Yes",COUNTIF($E$2:$E13,"Yes"),"") | H13: =IF(COUNTA(A13:E13)=0,"",IF(COUNTIF($A$2:$A$1000,A13)>1,"DUPLICATE YEAR_SEM",IF(OR(B13<1,B13>4,C13<1,C13>2),"INVALID YEAR/SEMESTER","OK")))
F14: =IFERROR(INDEX($A$2:$A$1000,MATCH(ROWS($F$2:F14),$G$2:$G$1000,0)),"") | G14: =IF($E14="Yes",COUNTIF($E$2:$E14,"Yes"),"") | H14: =IF(COUNTA(A14:E14)=0,"",IF(COUNTIF($A$2:$A$1000,A14)>1,"DUPLICATE YEAR_SEM",IF(OR(B14<1,B14>4,C14<1,C14>2),"INVALID YEAR/SEMESTER","OK")))
F15: =IFERROR(INDEX($A$2:$A$1000,MATCH(ROWS($F$2:F15),$G$2:$G$1000,0)),"") | G15: =IF($E15="Yes",COUNTIF($E$2:$E15,"Yes"),"") | H15: =IF(COUNTA(A15:E15)=0,"",IF(COUNTIF($A$2:$A$1000,A15)>1,"DUPLICATE YEAR_SEM",IF(OR(B15<1,B15>4,C15<1,C15>2),"INVALID YEAR/SEMESTER","OK")))
F16: =IFERROR(INDEX($A$2:$A$1000,MATCH(ROWS($F$2:F16),$G$2:$G$1000,0)),"") | G16: =IF($E16="Yes",COUNTIF($E$2:$E16,"Yes"),"") | H16: =IF(COUNTA(A16:E16)=0,"",IF(COUNTIF($A$2:$A$1000,A16)>1,"DUPLICATE YEAR_SEM",IF(OR(B16<1,B16>4,C16<1,C16>2),"INVALID YEAR/SEMESTER","OK")))
F17: =IFERROR(INDEX($A$2:$A$1000,MATCH(ROWS($F$2:F17),$G$2:$G$1000,0)),"") | G17: =IF($E17="Yes",COUNTIF($E$2:$E17,"Yes"),"") | H17: =IF(COUNTA(A17:E17)=0,"",IF(COUNTIF($A$2:$A$1000,A17)>1,"DUPLICATE YEAR_SEM",IF(OR(B17<1,B17>4,C17<1,C17>2),"INVALID YEAR/SEMESTER","OK")))
F18: =IFERROR(INDEX($A$2:$A$1000,MATCH(ROWS($F$2:F18),$G$2:$G$1000,0)),"") | G18: =IF($E18="Yes",COUNTIF($E$2:$E18,"Yes"),"") | H18: =IF(COUNTA(A18:E18)=0,"",IF(COUNTIF($A$2:$A$1000,A18)>1,"DUPLICATE YEAR_SEM",IF(OR(B18<1,B18>4,C18<1,C18>2),"INVALID YEAR/SEMESTER","OK")))
F19: =IFERROR(INDEX($A$2:$A$1000,MATCH(ROWS($F$2:F19),$G$2:$G$1000,0)),"") | G19: =IF($E19="Yes",COUNTIF($E$2:$E19,"Yes"),"") | H19: =IF(COUNTA(A19:E19)=0,"",IF(COUNTIF($A$2:$A$1000,A19)>1,"DUPLICATE YEAR_SEM",IF(OR(B19<1,B19>4,C19<1,C19>2),"INVALID YEAR/SEMESTER","OK")))
F20: =IFERROR(INDEX($A$2:$A$1000,MATCH(ROWS($F$2:F20),$G$2:$G$1000,0)),"") | G20: =IF($E20="Yes",COUNTIF($E$2:$E20,"Yes"),"") | H20: =IF(COUNTA(A20:E20)=0,"",IF(COUNTIF($A$2:$A$1000,A20)>1,"DUPLICATE YEAR_SEM",IF(OR(B20<1,B20>4,C20<1,C20>2),"INVALID YEAR/SEMESTER","OK")))
F21: =IFERROR(INDEX($A$2:$A$1000,MATCH(ROWS($F$2:F21),$G$2:$G$1000,0)),"") | G21: =IF($E21="Yes",COUNTIF($E$2:$E21,"Yes"),"") | H21: =IF(COUNTA(A21:E21)=0,"",IF(COUNTIF($A$2:$A$1000,A21)>1,"DUPLICATE YEAR_SEM",IF(OR(B21<1,B21>4,C21<1,C21>2),"INVALID YEAR/SEMESTER","OK")))
... F1000: =IFERROR(INDEX($A$2:$A$1000,MATCH(ROWS($F$2:F1000),$G$2:$G$1000,0)),"") | G1000: =IF($E1000="Yes",COUNTIF($E$2:$E1000,"Yes"),"") | H1000: =IF(COUNTA(A1000:E1000)=0,"",IF(COUNTIF($A$2:$A$1000,A1000)>1,"DUPLICATE YEAR_SEM",IF(OR(B1000<1,B1000>4,C1000<1,C1000>2),"INVALID YEAR/SEMESTER","OK")))

Sheet Teachers
A1: full_name * | B1: abbreviation * | C1: designation * | D1: department * | E1: status
A2: Dr. Mrinal Kanti Baowly | B2: DMKB | C2: Professor | D2: CSE | E2: =IF(COUNTA(A2:D2)=0,"",IF(COUNTIF($B$2:$B$500,B2)>1,"DUPLICATE ABBREVIATION","OK")) -> OK
A3: Dr. Saleh Ahmed | B3: DSA | C3: Associate Professor | D3: CSE | E3: =IF(COUNTA(A3:D3)=0,"",IF(COUNTIF($B$2:$B$500,B3)>1,"DUPLICATE ABBREVIATION","OK")) -> OK
A4: Md. Nesar Hossain | B4: MNH | C4: Associate Professor | D4: CSE | E4: =IF(COUNTA(A4:D4)=0,"",IF(COUNTIF($B$2:$B$500,B4)>1,"DUPLICATE ABBREVIATION","OK")) -> OK
A5: Abu-Bakar Muhammad Abdullah | B5: AMA | C5: Assistant Professor | D5: CSE | E5: =IF(COUNTA(A5:D5)=0,"",IF(COUNTIF($B$2:$B$500,B5)>1,"DUPLICATE ABBREVIATION","OK")) -> OK
A6: Faruk Hossen | B6: FH | C6: Assistant Professor | D6: CSE | E6: =IF(COUNTA(A6:D6)=0,"",IF(COUNTIF($B$2:$B$500,B6)>1,"DUPLICATE ABBREVIATION","OK")) -> OK
A7: Md. Ferdous | B7: MF | C7: Assistant Professor | D7: CSE | E7: =IF(COUNTA(A7:D7)=0,"",IF(COUNTIF($B$2:$B$500,B7)>1,"DUPLICATE ABBREVIATION","OK")) -> OK
A8: Nahida Islam | B8: NI | C8: Lecturer | D8: CSE | E8: =IF(COUNTA(A8:D8)=0,"",IF(COUNTIF($B$2:$B$500,B8)>1,"DUPLICATE ABBREVIATION","OK")) -> OK
A9: Sabina Yeasmin | B9: SY | C9: Assistant Professor | D9: Mathematics | E9: =IF(COUNTA(A9:D9)=0,"",IF(COUNTIF($B$2:$B$500,B9)>1,"DUPLICATE ABBREVIATION","OK")) -> OK
A10: Robiul Islam | B10: RI | C10: Assistant Professor | D10: EEE | E10: =IF(COUNTA(A10:D10)=0,"",IF(COUNTIF($B$2:$B$500,B10)>1,"DUPLICATE ABBREVIATION","OK")) -> OK
A11: Habibur Rahaman | B11: HR | C11: Associate Professor | D11: English | E11: =IF(COUNTA(A11:D11)=0,"",IF(COUNTIF($B$2:$B$500,B11)>1,"DUPLICATE ABBREVIATION","OK")) -> OK
A12: Md. Eyakub Ali | B12: MEA | C12: Assistant Professor | D12: EEE | E12: =IF(COUNTA(A12:D12)=0,"",IF(COUNTIF($B$2:$B$500,B12)>1,"DUPLICATE ABBREVIATION","OK")) -> OK
E13: =IF(COUNTA(A13:D13)=0,"",IF(COUNTIF($B$2:$B$500,B13)>1,"DUPLICATE ABBREVIATION","OK"))
E14: =IF(COUNTA(A14:D14)=0,"",IF(COUNTIF($B$2:$B$500,B14)>1,"DUPLICATE ABBREVIATION","OK"))
E15: =IF(COUNTA(A15:D15)=0,"",IF(COUNTIF($B$2:$B$500,B15)>1,"DUPLICATE ABBREVIATION","OK"))
E16: =IF(COUNTA(A16:D16)=0,"",IF(COUNTIF($B$2:$B$500,B16)>1,"DUPLICATE ABBREVIATION","OK"))
E17: =IF(COUNTA(A17:D17)=0,"",IF(COUNTIF($B$2:$B$500,B17)>1,"DUPLICATE ABBREVIATION","OK"))
E18: =IF(COUNTA(A18:D18)=0,"",IF(COUNTIF($B$2:$B$500,B18)>1,"DUPLICATE ABBREVIATION","OK"))
E19: =IF(COUNTA(A19:D19)=0,"",IF(COUNTIF($B$2:$B$500,B19)>1,"DUPLICATE ABBREVIATION","OK"))
E20: =IF(COUNTA(A20:D20)=0,"",IF(COUNTIF($B$2:$B$500,B20)>1,"DUPLICATE ABBREVIATION","OK"))
E21: =IF(COUNTA(A21:D21)=0,"",IF(COUNTIF($B$2:$B$500,B21)>1,"DUPLICATE ABBREVIATION","OK"))
E22: =IF(COUNTA(A22:D22)=0,"",IF(COUNTIF($B$2:$B$500,B22)>1,"DUPLICATE ABBREVIATION","OK"))
E23: =IF(COUNTA(A23:D23)=0,"",IF(COUNTIF($B$2:$B$500,B23)>1,"DUPLICATE ABBREVIATION","OK"))
E24: =IF(COUNTA(A24:D24)=0,"",IF(COUNTIF($B$2:$B$500,B24)>1,"DUPLICATE ABBREVIATION","OK"))
... E500: =IF(COUNTA(A500:D500)=0,"",IF(COUNTIF($B$2:$B$500,B500)>1,"DUPLICATE ABBREVIATION","OK"))

Sheet Credit_Rules
A1: credit * | B1: type * | C1: classes_per_week * | D1: duration_minutes * | E1: status
A2: 3 | B2: Theory | C2: 3 | D2: 50 | E2: =IF(COUNTA(A2:D2)=0,"",IF(COUNTIFS($A$2:$A$100,A2,$B$2:$B$100,B2)>1,"DUPLICATE CREDIT/TYPE","OK")) -> OK
A3: 2 | B3: Theory | C3: 2 | D3: 50 | E3: =IF(COUNTA(A3:D3)=0,"",IF(COUNTIFS($A$2:$A$100,A3,$B$2:$B$100,B3)>1,"DUPLICATE CREDIT/TYPE","OK")) -> OK
A4: 0.5 | B4: Lab | C4: 1 | D4: 50 | E4: =IF(COUNTA(A4:D4)=0,"",IF(COUNTIFS($A$2:$A$100,A4,$B$2:$B$100,B4)>1,"DUPLICATE CREDIT/TYPE","OK")) -> OK
A5: 1 | B5: Lab | C5: 1 | D5: 100 | E5: =IF(COUNTA(A5:D5)=0,"",IF(COUNTIFS($A$2:$A$100,A5,$B$2:$B$100,B5)>1,"DUPLICATE CREDIT/TYPE","OK")) -> OK
A6: 1.5 | B6: Lab | C6: 1 | D6: 100 | E6: =IF(COUNTA(A6:D6)=0,"",IF(COUNTIFS($A$2:$A$100,A6,$B$2:$B$100,B6)>1,"DUPLICATE CREDIT/TYPE","OK")) -> OK
E7: =IF(COUNTA(A7:D7)=0,"",IF(COUNTIFS($A$2:$A$100,A7,$B$2:$B$100,B7)>1,"DUPLICATE CREDIT/TYPE","OK"))
E8: =IF(COUNTA(A8:D8)=0,"",IF(COUNTIFS($A$2:$A$100,A8,$B$2:$B$100,B8)>1,"DUPLICATE CREDIT/TYPE","OK"))
E9: =IF(COUNTA(A9:D9)=0,"",IF(COUNTIFS($A$2:$A$100,A9,$B$2:$B$100,B9)>1,"DUPLICATE CREDIT/TYPE","OK"))
E10: =IF(COUNTA(A10:D10)=0,"",IF(COUNTIFS($A$2:$A$100,A10,$B$2:$B$100,B10)>1,"DUPLICATE CREDIT/TYPE","OK"))
E11: =IF(COUNTA(A11:D11)=0,"",IF(COUNTIFS($A$2:$A$100,A11,$B$2:$B$100,B11)>1,"DUPLICATE CREDIT/TYPE","OK"))
E12: =IF(COUNTA(A12:D12)=0,"",IF(COUNTIFS($A$2:$A$100,A12,$B$2:$B$100,B12)>1,"DUPLICATE CREDIT/TYPE","OK"))
E13: =IF(COUNTA(A13:D13)=0,"",IF(COUNTIFS($A$2:$A$100,A13,$B$2:$B$100,B13)>1,"DUPLICATE CREDIT/TYPE","OK"))
E14: =IF(COUNTA(A14:D14)=0,"",IF(COUNTIFS($A$2:$A$100,A14,$B$2:$B$100,B14)>1,"DUPLICATE CREDIT/TYPE","OK"))
E15: =IF(COUNTA(A15:D15)=0,"",IF(COUNTIFS($A$2:$A$100,A15,$B$2:$B$100,B15)>1,"DUPLICATE CREDIT/TYPE","OK"))
E16: =IF(COUNTA(A16:D16)=0,"",IF(COUNTIFS($A$2:$A$100,A16,$B$2:$B$100,B16)>1,"DUPLICATE CREDIT/TYPE","OK"))
E17: =IF(COUNTA(A17:D17)=0,"",IF(COUNTIFS($A$2:$A$100,A17,$B$2:$B$100,B17)>1,"DUPLICATE CREDIT/TYPE","OK"))
E18: =IF(COUNTA(A18:D18)=0,"",IF(COUNTIFS($A$2:$A$100,A18,$B$2:$B$100,B18)>1,"DUPLICATE CREDIT/TYPE","OK"))
... E100: =IF(COUNTA(A100:D100)=0,"",IF(COUNTIFS($A$2:$A$100,A100,$B$2:$B$100,B100)>1,"DUPLICATE CREDIT/TYPE","OK"))

Sheet Courses
A1: course_code * | B1: course_name * | C1: credit * | D1: dept * | E1: year_sem * | F1: teacher_abbr * | G1: status
A2: CSE401 | B2: Digital Signal Processing | C2: 3 | D2: CSE | E2: 4-1 | F2: NI | G2: =IF(COUNTA(A2:F2)=0,"",IF(COUNTIF($A$2:$A$1000,A2)>1,"DUPLICATE COURSE CODE","OK")) -> OK
A3: CSE402 | B3: Digital Signal Processing Sessional | C3: 1 | D3: CSE | E3: 4-1 | F3: NI | G3: =IF(COUNTA(A3:F3)=0,"",IF(COUNTIF($A$2:$A$1000,A3)>1,"DUPLICATE COURSE CODE","OK")) -> OK
A4: CSE403 | B4: Digital Image Processing and Analysis | C4: 3 | D4: CSE | E4: 4-1 | F4: MF | G4: =IF(COUNTA(A4:F4)=0,"",IF(COUNTIF($A$2:$A$1000,A4)>1,"DUPLICATE COURSE CODE","OK")) -> OK
A5: CSE404 | B5: Digital Image Processing and Analysis Sessional | C5: 1 | D5: CSE | E5: 4-1 | F5: MF | G5: =IF(COUNTA(A5:F5)=0,"",IF(COUNTIF($A$2:$A$1000,A5)>1,"DUPLICATE COURSE CODE","OK")) -> OK
A6: CSE405 | B6: Machine Learning | C6: 3 | D6: CSE | E6: 4-1 | F6: DMKB | G6: =IF(COUNTA(A6:F6)=0,"",IF(COUNTIF($A$2:$A$1000,A6)>1,"DUPLICATE COURSE CODE","OK")) -> OK
A7: CSE406 | B7: Machine Learning Sessional | C7: 1.5 | D7: CSE | E7: 4-1 | F7: DMKB | G7: =IF(COUNTA(A7:F7)=0,"",IF(COUNTIF($A$2:$A$1000,A7)>1,"DUPLICATE COURSE CODE","OK")) -> OK
A8: CSE413 | B8: Simulation and Modeling | C8: 3 | D8: CSE | E8: 4-1 | F8: MNH | G8: =IF(COUNTA(A8:F8)=0,"",IF(COUNTIF($A$2:$A$1000,A8)>1,"DUPLICATE COURSE CODE","OK")) -> OK
A9: CSE414 | B9: Simulation and Modeling | C9: 0.5 | D9: CSE | E9: 4-1 | F9: MNH | G9: =IF(COUNTA(A9:F9)=0,"",IF(COUNTIF($A$2:$A$1000,A9)>1,"DUPLICATE COURSE CODE","OK")) -> OK
A10: CSE351 | B10: Operating System | C10: 3 | D10: CSE | E10: 3-2 | F10: DSA | G10: =IF(COUNTA(A10:F10)=0,"",IF(COUNTIF($A$2:$A$1000,A10)>1,"DUPLICATE COURSE CODE","OK")) -> OK
A11: CSE352 | B11: Operating System Sessional | C11: 1 | D11: CSE | E11: 3-2 | F11: DSA | G11: =IF(COUNTA(A11:F11)=0,"",IF(COUNTIF($A$2:$A$1000,A11)>1,"DUPLICATE COURSE CODE","OK")) -> OK
A12: CSE353 | B12: Communication Engineering | C12: 3 | D12: CSE | E12: 3-2 | F12: NI | G12: =IF(COUNTA(A12:F12)=0,"",IF(COUNTIF($A$2:$A$1000,A12)>1,"DUPLICATE COURSE CODE","OK")) -> OK
A13: CSE354 | B13: Communication Engineering Sessional | C13: 1 | D13: CSE | E13: 3-2 | F13: NI | G13: =IF(COUNTA(A13:F13)=0,"",IF(COUNTIF($A$2:$A$1000,A13)>1,"DUPLICATE COURSE CODE","OK")) -> OK
A14: CSE355 | B14: Software Engineering | C14: 3 | D14: CSE | E14: 3-2 | F14: DMKB | G14: =IF(COUNTA(A14:F14)=0,"",IF(COUNTIF($A$2:$A$1000,A14)>1,"DUPLICATE COURSE CODE","OK")) -> OK
A15: CSE356 | B15: Software Engineering Sessional | C15: 1 | D15: CSE | E15: 3-2 | F15: DMKB | G15: =IF(COUNTA(A15:F15)=0,"",IF(COUNTIF($A$2:$A$1000,A15)>1,"DUPLICATE COURSE CODE","OK")) -> OK
A16: CSE357 | B16: Artificial Intelligence | C16: 3 | D16: CSE | E16: 3-2 | F16: MNH | G16: =IF(COUNTA(A16:F16)=0,"",IF(COUNTIF($A$2:$A$1000,A16)>1,"DUPLICATE COURSE CODE","OK")) -> OK
A17: CSE358 | B17: Artificial Intelligence Sessional | C17: 1 | D17: CSE | E17: 3-2 | F17: MNH | G17: =IF(COUNTA(A17:F17)=0,"",IF(COUNTIF($A$2:$A$1000,A17)>1,"DUPLICATE COURSE CODE","OK")) -> OK
A18: CSE359 | B18: Compiler Design | C18: 3 | D18: CSE | E18: 3-2 | F18: FH | G18: =IF(COUNTA(A18:F18)=0,"",IF(COUNTIF($A$2:$A$1000,A18)>1,"DUPLICATE COURSE CODE","OK")) -> OK
A19: CSE360 | B19: Compiler Design Sessional | C19: 1 | D19: CSE | E19: 3-2 | F19: FH | G19: =IF(COUNTA(A19:F19)=0,"",IF(COUNTIF($A$2:$A$1000,A19)>1,"DUPLICATE COURSE CODE","OK")) -> OK
A20: CSE252 | B20: Tecnical writing and presentation LAB | C20: 0.5 | D20: CSE | E20: 2-2 | F20: AMA | G20: =IF(COUNTA(A20:F20)=0,"",IF(COUNTIF($A$2:$A$1000,A20)>1,"DUPLICATE COURSE CODE","OK")) -> OK
A21: CSE253 | B21: Algorithm Analysis and Design | C21: 3 | D21: CSE | E21: 2-2 | F21: AMA | G21: =IF(COUNTA(A21:F21)=0,"",IF(COUNTIF($A$2:$A$1000,A21)>1,"DUPLICATE COURSE CODE","OK")) -> OK
A22: CSE254 | B22: Algorithm Analysis and Design LAB | C22: 1.5 | D22: CSE | E22: 2-2 | F22: AMA | G22: =IF(COUNTA(A22:F22)=0,"",IF(COUNTIF($A$2:$A$1000,A22)>1,"DUPLICATE COURSE CODE","OK")) -> OK
A23: CSE255 | B23: Numerical Methods | C23: 3 | D23: CSE | E23: 2-2 | F23: NI | G23: =IF(COUNTA(A23:F23)=0,"",IF(COUNTIF($A$2:$A$1000,A23)>1,"DUPLICATE COURSE CODE","OK")) -> OK
A24: CSE256 | B24: Numerical Methods LAB | C24: 1 | D24: CSE | E24: 2-2 | F24: NI | G24: =IF(COUNTA(A24:F24)=0,"",IF(COUNTIF($A$2:$A$1000,A24)>1,"DUPLICATE COURSE CODE","OK")) -> OK
A25: CSE257 | B25: Computer Architecture and Organization | C25: 3 | D25: CSE | E25: 2-2 | F25: FH | G25: =IF(COUNTA(A25:F25)=0,"",IF(COUNTIF($A$2:$A$1000,A25)>1,"DUPLICATE COURSE CODE","OK")) -> OK
A26: CSE258 | B26: Computer Architecture and Organization LAB | C26: 1 | D26: CSE | E26: 2-2 | F26: FH | G26: =IF(COUNTA(A26:F26)=0,"",IF(COUNTIF($A$2:$A$1000,A26)>1,"DUPLICATE COURSE CODE","OK")) -> OK
A27: CSE259 | B27: Theory of Computation | C27: 2 | D27: CSE | E27: 2-2 | F27: AMA | G27: =IF(COUNTA(A27:F27)=0,"",IF(COUNTIF($A$2:$A$1000,A27)>1,"DUPLICATE COURSE CODE","OK")) -> OK
A28: MAT265 | B28: Complex Variable, Partial Differential Equation and Harmonic Analysis | C28: 3 | D28: Mathematics | E28: 2-2 | F28: SY | G28: =IF(COUNTA(A28:F28)=0,"",IF(COUNTIF($A$2:$A$1000,A28)>1,"DUPLICATE COURSE CODE","OK")) -> OK
A29: CSE201 | B29: Data Structure | C29: 3 | D29: CSE | E29: 2-1 | F29: FH | G29: =IF(COUNTA(A29:F29)=0,"",IF(COUNTIF($A$2:$A$1000,A29)>1,"DUPLICATE COURSE CODE","OK")) -> OK
A30: CSE202 | B30: Data Structure Sessional | C30: 1 | D30: CSE | E30: 2-1 | F30: FH | G30: =IF(COUNTA(A30:F30)=0,"",IF(COUNTIF($A$2:$A$1000,A30)>1,"DUPLICATE COURSE CODE","OK")) -> OK
A31: CSE203 | B31: Object Oriented Programming II (Python) | C31: 3 | D31: CSE | E31: 2-1 | F31: AMA | G31: =IF(COUNTA(A31:F31)=0,"",IF(COUNTIF($A$2:$A$1000,A31)>1,"DUPLICATE COURSE CODE","OK")) -> OK
A32: CSE204 | B32: Object Oriented Programming II (Python) Sessional | C32: 1 | D32: CSE | E32: 2-1 | F32: AMA | G32: =IF(COUNTA(A32:F32)=0,"",IF(COUNTIF($A$2:$A$1000,A32)>1,"DUPLICATE COURSE CODE","OK")) -> OK
A33: CSE205 | B33: Digatal Logic Design | C33: 3 | D33: CSE | E33: 2-1 | F33: DSA | G33: =IF(COUNTA(A33:F33)=0,"",IF(COUNTIF($A$2:$A$1000,A33)>1,"DUPLICATE COURSE CODE","OK")) -> OK
A34: CSE206 | B34: Digatal Logic Design Sessional | C34: 1 | D34: CSE | E34: 2-1 | F34: DSA | G34: =IF(COUNTA(A34:F34)=0,"",IF(COUNTIF($A$2:$A$1000,A34)>1,"DUPLICATE COURSE CODE","OK")) -> OK
A35: EEE207 | B35: Electrical Drives | C35: 3 | D35: EEE | E35: 2-1 | F35: MEA | G35: =IF(COUNTA(A35:F35)=0,"",IF(COUNTIF($A$2:$A$1000,A35)>1,"DUPLICATE COURSE CODE","OK")) -> OK
A36: ENG112 | B36: Functional English Sessional | C36: 1 | D36: English | E36: 1-1 | F36: HR | G36: =IF(COUNTA(A36:F36)=0,"",IF(COUNTIF($A$2:$A$1000,A36)>1,"DUPLICATE COURSE CODE","OK")) -> OK
A37: ENG111 | B37: Functional English | C37: 2 | D37: English | E37: 1-1 | F37: HR | G37: =IF(COUNTA(A37:F37)=0,"",IF(COUNTIF($A$2:$A$1000,A37)>1,"DUPLICATE COURSE CODE","OK")) -> OK
A38: MAT109 | B38: Defferential and Integral Calculus | C38: 3 | D38: Mathematics | E38: 1-1 | F38: SY | G38: =IF(COUNTA(A38:F38)=0,"",IF(COUNTIF($A$2:$A$1000,A38)>1,"DUPLICATE COURSE CODE","OK")) -> OK
A39: EEE108 | B39: Basic Electrical Engineering Sessional | C39: 1 | D39: EEE | E39: 1-1 | F39: RI | G39: =IF(COUNTA(A39:F39)=0,"",IF(COUNTIF($A$2:$A$1000,A39)>1,"DUPLICATE COURSE CODE","OK")) -> OK
A40: EEE107 | B40: Basic Electrical Engineering | C40: 2 | D40: EEE | E40: 1-1 | F40: MEA | G40: =IF(COUNTA(A40:F40)=0,"",IF(COUNTIF($A$2:$A$1000,A40)>1,"DUPLICATE COURSE CODE","OK")) -> OK
...

Sheet Rooms
A1: room_id * | B1: room_name * | C1: type * | D1: status
A2: R407 | B2: Room 407 | C2: lab | D2: =IF(COUNTA(A2:C2)=0,"",IF(COUNTIF($A$2:$A$500,A2)>1,"DUPLICATE ROOM ID","OK")) -> OK
A3: R505 | B3: Room 505 | C3: lab | D3: =IF(COUNTA(A3:C3)=0,"",IF(COUNTIF($A$2:$A$500,A3)>1,"DUPLICATE ROOM ID","OK")) -> OK
A4: R411A | B4: Room 411A | C4: classroom | D4: =IF(COUNTA(A4:C4)=0,"",IF(COUNTIF($A$2:$A$500,A4)>1,"DUPLICATE ROOM ID","OK")) -> OK
A5: R408 | B5: Room 408 | C5: classroom | D5: =IF(COUNTA(A5:C5)=0,"",IF(COUNTIF($A$2:$A$500,A5)>1,"DUPLICATE ROOM ID","OK")) -> OK
A6: R406 | B6: Room 406 | C6: classroom | D6: =IF(COUNTA(A6:C6)=0,"",IF(COUNTIF($A$2:$A$500,A6)>1,"DUPLICATE ROOM ID","OK")) -> OK
D7: =IF(COUNTA(A7:C7)=0,"",IF(COUNTIF($A$2:$A$500,A7)>1,"DUPLICATE ROOM ID","OK"))
D8: =IF(COUNTA(A8:C8)=0,"",IF(COUNTIF($A$2:$A$500,A8)>1,"DUPLICATE ROOM ID","OK"))
D9: =IF(COUNTA(A9:C9)=0,"",IF(COUNTIF($A$2:$A$500,A9)>1,"DUPLICATE ROOM ID","OK"))
D10: =IF(COUNTA(A10:C10)=0,"",IF(COUNTIF($A$2:$A$500,A10)>1,"DUPLICATE ROOM ID","OK"))
D11: =IF(COUNTA(A11:C11)=0,"",IF(COUNTIF($A$2:$A$500,A11)>1,"DUPLICATE ROOM ID","OK"))
D12: =IF(COUNTA(A12:C12)=0,"",IF(COUNTIF($A$2:$A$500,A12)>1,"DUPLICATE ROOM ID","OK"))
D13: =IF(COUNTA(A13:C13)=0,"",IF(COUNTIF($A$2:$A$500,A13)>1,"DUPLICATE ROOM ID","OK"))
D14: =IF(COUNTA(A14:C14)=0,"",IF(COUNTIF($A$2:$A$500,A14)>1,"DUPLICATE ROOM ID","OK"))
D15: =IF(COUNTA(A15:C15)=0,"",IF(COUNTIF($A$2:$A$500,A15)>1,"DUPLICATE ROOM ID","OK"))
D16: =IF(COUNTA(A16:C16)=0,"",IF(COUNTIF($A$2:$A$500,A16)>1,"DUPLICATE ROOM ID","OK"))
D17: =IF(COUNTA(A17:C17)=0,"",IF(COUNTIF($A$2:$A$500,A17)>1,"DUPLICATE ROOM ID","OK"))
D18: =IF(COUNTA(A18:C18)=0,"",IF(COUNTIF($A$2:$A$500,A18)>1,"DUPLICATE ROOM ID","OK"))
... D500: =IF(COUNTA(A500:C500)=0,"",IF(COUNTIF($A$2:$A$500,A500)>1,"DUPLICATE ROOM ID","OK"))

Sheet Room_Preference
A1: room_id * | B1: year_group * | C1: weight_percent * | D1: status
A2: R407 | B2: 1-2 | C2: 30 | D2: =IF(COUNTA(A2:C2)=0,"",IF(OR(C2<0,C2>100),"INVALID PERCENT",IF(COUNTIFS($A$2:$A$1000,A2,$B$2:$B$1000,B2)>1,"DUPLICATE ROOM/GROUP","OK"))) -> OK
A3: =IF(OR(A2="",B2=""),"",A2) -> R407 | B3: =IF(B2="","",IF(B2="1-2","3-4",IF(B2="3-4","1-2",""))) -> 3-4 | C3: =IF(OR(A2="",C2=""),"",100-C2) -> 70 | D3: =IF(COUNTA(A3:C3)=0,"",IF(OR(C3<0,C3>100),"INVALID PERCENT",IF(COUNTIFS($A$2:$A$1000,A3,$B$2:$B$1000,B3)>1,"DUPLICATE ROOM/GROUP","OK"))) -> OK
A4: R408 | B4: 1-2 | C4: 20 | D4: =IF(COUNTA(A4:C4)=0,"",IF(OR(C4<0,C4>100),"INVALID PERCENT",IF(COUNTIFS($A$2:$A$1000,A4,$B$2:$B$1000,B4)>1,"DUPLICATE ROOM/GROUP","OK"))) -> OK
A5: =IF(OR(A4="",B4=""),"",A4) -> R408 | B5: =IF(B4="","",IF(B4="1-2","3-4",IF(B4="3-4","1-2",""))) -> 3-4 | C5: =IF(OR(A4="",C4=""),"",100-C4) -> 80 | D5: =IF(COUNTA(A5:C5)=0,"",IF(OR(C5<0,C5>100),"INVALID PERCENT",IF(COUNTIFS($A$2:$A$1000,A5,$B$2:$B$1000,B5)>1,"DUPLICATE ROOM/GROUP","OK"))) -> OK
A6: R505 | B6: 1-2 | C6: 70 | D6: =IF(COUNTA(A6:C6)=0,"",IF(OR(C6<0,C6>100),"INVALID PERCENT",IF(COUNTIFS($A$2:$A$1000,A6,$B$2:$B$1000,B6)>1,"DUPLICATE ROOM/GROUP","OK"))) -> OK
A7: =IF(OR(A6="",B6=""),"",A6) -> R505 | B7: =IF(B6="","",IF(B6="1-2","3-4",IF(B6="3-4","1-2",""))) -> 3-4 | C7: =IF(OR(A6="",C6=""),"",100-C6) -> 30 | D7: =IF(COUNTA(A7:C7)=0,"",IF(OR(C7<0,C7>100),"INVALID PERCENT",IF(COUNTIFS($A$2:$A$1000,A7,$B$2:$B$1000,B7)>1,"DUPLICATE ROOM/GROUP","OK"))) -> OK
A8: R411A | B8: 1-2 | C8: 80 | D8: =IF(COUNTA(A8:C8)=0,"",IF(OR(C8<0,C8>100),"INVALID PERCENT",IF(COUNTIFS($A$2:$A$1000,A8,$B$2:$B$1000,B8)>1,"DUPLICATE ROOM/GROUP","OK"))) -> OK
A9: =IF(OR(A8="",B8=""),"",A8) -> R411A | B9: =IF(B8="","",IF(B8="1-2","3-4",IF(B8="3-4","1-2",""))) -> 3-4 | C9: =IF(OR(A8="",C8=""),"",100-C8) -> 20 | D9: =IF(COUNTA(A9:C9)=0,"",IF(OR(C9<0,C9>100),"INVALID PERCENT",IF(COUNTIFS($A$2:$A$1000,A9,$B$2:$B$1000,B9)>1,"DUPLICATE ROOM/GROUP","OK"))) -> OK
A10: R406 | B10: 1-2 | C10: 50 | D10: =IF(COUNTA(A10:C10)=0,"",IF(OR(C10<0,C10>100),"INVALID PERCENT",IF(COUNTIFS($A$2:$A$1000,A10,$B$2:$B$1000,B10)>1,"DUPLICATE ROOM/GROUP","OK"))) -> OK
A11: =IF(OR(A10="",B10=""),"",A10) -> R406 | B11: =IF(B10="","",IF(B10="1-2","3-4",IF(B10="3-4","1-2",""))) -> 3-4 | C11: =IF(OR(A10="",C10=""),"",100-C10) -> 50 | D11: =IF(COUNTA(A11:C11)=0,"",IF(OR(C11<0,C11>100),"INVALID PERCENT",IF(COUNTIFS($A$2:$A$1000,A11,$B$2:$B$1000,B11)>1,"DUPLICATE ROOM/GROUP","OK"))) -> OK
D12: =IF(COUNTA(A12:C12)=0,"",IF(OR(C12<0,C12>100),"INVALID PERCENT",IF(COUNTIFS($A$2:$A$1000,A12,$B$2:$B$1000,B12)>1,"DUPLICATE ROOM/GROUP","OK")))
A13: =IF(OR(A12="",B12=""),"",A12) | B13: =IF(B12="","",IF(B12="1-2","3-4",IF(B12="3-4","1-2",""))) | C13: =IF(OR(A12="",C12=""),"",100-C12) | D13: =IF(COUNTA(A13:C13)=0,"",IF(OR(C13<0,C13>100),"INVALID PERCENT",IF(COUNTIFS($A$2:$A$1000,A13,$B$2:$B$1000,B13)>1,"DUPLICATE ROOM/GROUP","OK"))) -> INVALID PERCENT
D14: =IF(COUNTA(A14:C14)=0,"",IF(OR(C14<0,C14>100),"INVALID PERCENT",IF(COUNTIFS($A$2:$A$1000,A14,$B$2:$B$1000,B14)>1,"DUPLICATE ROOM/GROUP","OK")))
A15: =IF(OR(A14="",B14=""),"",A14) | B15: =IF(B14="","",IF(B14="1-2","3-4",IF(B14="3-4","1-2",""))) | C15: =IF(OR(A14="",C14=""),"",100-C14) | D15: =IF(COUNTA(A15:C15)=0,"",IF(OR(C15<0,C15>100),"INVALID PERCENT",IF(COUNTIFS($A$2:$A$1000,A15,$B$2:$B$1000,B15)>1,"DUPLICATE ROOM/GROUP","OK"))) -> INVALID PERCENT
D16: =IF(COUNTA(A16:C16)=0,"",IF(OR(C16<0,C16>100),"INVALID PERCENT",IF(COUNTIFS($A$2:$A$1000,A16,$B$2:$B$1000,B16)>1,"DUPLICATE ROOM/GROUP","OK")))
A17: =IF(OR(A16="",B16=""),"",A16) | B17: =IF(B16="","",IF(B16="1-2","3-4",IF(B16="3-4","1-2",""))) | C17: =IF(OR(A16="",C16=""),"",100-C16) | D17: =IF(COUNTA(A17:C17)=0,"",IF(OR(C17<0,C17>100),"INVALID PERCENT",IF(COUNTIFS($A$2:$A$1000,A17,$B$2:$B$1000,B17)>1,"DUPLICATE ROOM/GROUP","OK"))) -> INVALID PERCENT
D18: =IF(COUNTA(A18:C18)=0,"",IF(OR(C18<0,C18>100),"INVALID PERCENT",IF(COUNTIFS($A$2:$A$1000,A18,$B$2:$B$1000,B18)>1,"DUPLICATE ROOM/GROUP","OK")))
A19: =IF(OR(A18="",B18=""),"",A18) | B19: =IF(B18="","",IF(B18="1-2","3-4",IF(B18="3-4","1-2",""))) | C19: =IF(OR(A18="",C18=""),"",100-C18) | D19: =IF(COUNTA(A19:C19)=0,"",IF(OR(C19<0,C19>100),"INVALID PERCENT",IF(COUNTIFS($A$2:$A$1000,A19,$B$2:$B$1000,B19)>1,"DUPLICATE ROOM/GROUP","OK"))) -> INVALID PERCENT
D20: =IF(COUNTA(A20:C20)=0,"",IF(OR(C20<0,C20>100),"INVALID PERCENT",IF(COUNTIFS($A$2:$A$1000,A20,$B$2:$B$1000,B20)>1,"DUPLICATE ROOM/GROUP","OK")))
A21: =IF(OR(A20="",B20=""),"",A20) | B21: =IF(B20="","",IF(B20="1-2","3-4",IF(B20="3-4","1-2",""))) | C21: =IF(OR(A20="",C20=""),"",100-C20) | D21: =IF(COUNTA(A21:C21)=0,"",IF(OR(C21<0,C21>100),"INVALID PERCENT",IF(COUNTIFS($A$2:$A$1000,A21,$B$2:$B$1000,B21)>1,"DUPLICATE ROOM/GROUP","OK"))) -> INVALID PERCENT
D22: =IF(COUNTA(A22:C22)=0,"",IF(OR(C22<0,C22>100),"INVALID PERCENT",IF(COUNTIFS($A$2:$A$1000,A22,$B$2:$B$1000,B22)>1,"DUPLICATE ROOM/GROUP","OK")))
A23: =IF(OR(A22="",B22=""),"",A22) | B23: =IF(B22="","",IF(B22="1-2","3-4",IF(B22="3-4","1-2",""))) | C23: =IF(OR(A22="",C22=""),"",100-C22) | D23: =IF(COUNTA(A23:C23)=0,"",IF(OR(C23<0,C23>100),"INVALID PERCENT",IF(COUNTIFS($A$2:$A$1000,A23,$B$2:$B$1000,B23)>1,"DUPLICATE ROOM/GROUP","OK"))) -> INVALID PERCENT
D24: =IF(COUNTA(A24:C24)=0,"",IF(OR(C24<0,C24>100),"INVALID PERCENT",IF(COUNTIFS($A$2:$A$1000,A24,$B$2:$B$1000,B24)>1,"DUPLICATE ROOM/GROUP","OK")))
A25: =IF(OR(A24="",B24=""),"",A24) | B25: =IF(B24="","",IF(B24="1-2","3-4",IF(B24="3-4","1-2",""))) | C25: =IF(OR(A24="",C24=""),"",100-C24) | D25: =IF(COUNTA(A25:C25)=0,"",IF(OR(C25<0,C25>100),"INVALID PERCENT",IF(COUNTIFS($A$2:$A$1000,A25,$B$2:$B$1000,B25)>1,"DUPLICATE ROOM/GROUP","OK"))) -> INVALID PERCENT
D26: =IF(COUNTA(A26:C26)=0,"",IF(OR(C26<0,C26>100),"INVALID PERCENT",IF(COUNTIFS($A$2:$A$1000,A26,$B$2:$B$1000,B26)>1,"DUPLICATE ROOM/GROUP","OK")))
A27: =IF(OR(A26="",B26=""),"",A26) | B27: =IF(B26="","",IF(B26="1-2","3-4",IF(B26="3-4","1-2",""))) | C27: =IF(OR(A26="",C26=""),"",100-C26) | D27: =IF(COUNTA(A27:C27)=0,"",IF(OR(C27<0,C27>100),"INVALID PERCENT",IF(COUNTIFS($A$2:$A$1000,A27,$B$2:$B$1000,B27)>1,"DUPLICATE ROOM/GROUP","OK"))) -> INVALID PERCENT
D28: =IF(COUNTA(A28:C28)=0,"",IF(OR(C28<0,C28>100),"INVALID PERCENT",IF(COUNTIFS($A$2:$A$1000,A28,$B$2:$B$1000,B28)>1,"DUPLICATE ROOM/GROUP","OK")))
A29: =IF(OR(A28="",B28=""),"",A28) | B29: =IF(B28="","",IF(B28="1-2","3-4",IF(B28="3-4","1-2",""))) | C29: =IF(OR(A28="",C28=""),"",100-C28) | D29: =IF(COUNTA(A29:C29)=0,"",IF(OR(C29<0,C29>100),"INVALID PERCENT",IF(COUNTIFS($A$2:$A$1000,A29,$B$2:$B$1000,B29)>1,"DUPLICATE ROOM/GROUP","OK"))) -> INVALID PERCENT
D30: =IF(COUNTA(A30:C30)=0,"",IF(OR(C30<0,C30>100),"INVALID PERCENT",IF(COUNTIFS($A$2:$A$1000,A30,$B$2:$B$1000,B30)>1,"DUPLICATE ROOM/GROUP","OK")))
A31: =IF(OR(A30="",B30=""),"",A30) | B31: =IF(B30="","",IF(B30="1-2","3-4",IF(B30="3-4","1-2",""))) | C31: =IF(OR(A30="",C30=""),"",100-C30) | D31: =IF(COUNTA(A31:C31)=0,"",IF(OR(C31<0,C31>100),"INVALID PERCENT",IF(COUNTIFS($A$2:$A$1000,A31,$B$2:$B$1000,B31)>1,"DUPLICATE ROOM/GROUP","OK"))) -> INVALID PERCENT
D32: =IF(COUNTA(A32:C32)=0,"",IF(OR(C32<0,C32>100),"INVALID PERCENT",IF(COUNTIFS($A$2:$A$1000,A32,$B$2:$B$1000,B32)>1,"DUPLICATE ROOM/GROUP","OK")))
A33: =IF(OR(A32="",B32=""),"",A32) | B33: =IF(B32="","",IF(B32="1-2","3-4",IF(B32="3-4","1-2",""))) | C33: =IF(OR(A32="",C32=""),"",100-C32) | D33: =IF(COUNTA(A33:C33)=0,"",IF(OR(C33<0,C33>100),"INVALID PERCENT",IF(COUNTIFS($A$2:$A$1000,A33,$B$2:$B$1000,B33)>1,"DUPLICATE ROOM/GROUP","OK"))) -> INVALID PERCENT
D34: =IF(COUNTA(A34:C34)=0,"",IF(OR(C34<0,C34>100),"INVALID PERCENT",IF(COUNTIFS($A$2:$A$1000,A34,$B$2:$B$1000,B34)>1,"DUPLICATE ROOM/GROUP","OK")))
A35: =IF(OR(A34="",B34=""),"",A34) | B35: =IF(B34="","",IF(B34="1-2","3-4",IF(B34="3-4","1-2",""))) | C35: =IF(OR(A34="",C34=""),"",100-C34) | D35: =IF(COUNTA(A35:C35)=0,"",IF(OR(C35<0,C35>100),"INVALID PERCENT",IF(COUNTIFS($A$2:$A$1000,A35,$B$2:$B$1000,B35)>1,"DUPLICATE ROOM/GROUP","OK"))) -> INVALID PERCENT
D36: =IF(COUNTA(A36:C36)=0,"",IF(OR(C36<0,C36>100),"INVALID PERCENT",IF(COUNTIFS($A$2:$A$1000,A36,$B$2:$B$1000,B36)>1,"DUPLICATE ROOM/GROUP","OK")))
A37: =IF(OR(A36="",B36=""),"",A36) | B37: =IF(B36="","",IF(B36="1-2","3-4",IF(B36="3-4","1-2",""))) | C37: =IF(OR(A36="",C36=""),"",100-C36) | D37: =IF(COUNTA(A37:C37)=0,"",IF(OR(C37<0,C37>100),"INVALID PERCENT",IF(COUNTIFS($A$2:$A$1000,A37,$B$2:$B$1000,B37)>1,"DUPLICATE ROOM/GROUP","OK"))) -> INVALID PERCENT
D38: =IF(COUNTA(A38:C38)=0,"",IF(OR(C38<0,C38>100),"INVALID PERCENT",IF(COUNTIFS($A$2:$A$1000,A38,$B$2:$B$1000,B38)>1,"DUPLICATE ROOM/GROUP","OK")))
A39: =IF(OR(A38="",B38=""),"",A38) | B39: =IF(B38="","",IF(B38="1-2","3-4",IF(B38="3-4","1-2",""))) | C39: =IF(OR(A38="",C38=""),"",100-C38) | D39: =IF(COUNTA(A39:C39)=0,"",IF(OR(C39<0,C39>100),"INVALID PERCENT",IF(COUNTIFS($A$2:$A$1000,A39,$B$2:$B$1000,B39)>1,"DUPLICATE ROOM/GROUP","OK"))) -> INVALID PERCENT
D40: =IF(COUNTA(A40:C40)=0,"",IF(OR(C40<0,C40>100),"INVALID PERCENT",IF(COUNTIFS($A$2:$A$1000,A40,$B$2:$B$1000,B40)>1,"DUPLICATE ROOM/GROUP","OK")))
...

Sheet Day_Preference
A1: day * | B1: class_type * | C1: weight_percent * | D1: status
A2: SUN | B2: Lab | C2: 40 | D2: =IF(COUNTA(A2:C2)=0,"",IF(OR(C2<0,C2>100),"INVALID PERCENT",IF(COUNTIFS($A$2:$A$500,A2,$B$2:$B$500,B2)>1,"DUPLICATE DAY/CLASS","OK"))) -> OK
A3: =IF(OR(A2="",B2=""),"",A2) -> SUN | B3: =IF(B2="","",IF(B2="Lab","Theory",IF(B2="Theory","Lab",""))) -> Theory | C3: =IF(OR(A2="",C2=""),"",100-C2) -> 60 | D3: =IF(COUNTA(A3:C3)=0,"",IF(OR(C3<0,C3>100),"INVALID PERCENT",IF(COUNTIFS($A$2:$A$500,A3,$B$2:$B$500,B3)>1,"DUPLICATE DAY/CLASS","OK"))) -> OK
A4: MON | B4: Lab | C4: 40 | D4: =IF(COUNTA(A4:C4)=0,"",IF(OR(C4<0,C4>100),"INVALID PERCENT",IF(COUNTIFS($A$2:$A$500,A4,$B$2:$B$500,B4)>1,"DUPLICATE DAY/CLASS","OK"))) -> OK
A5: =IF(OR(A4="",B4=""),"",A4) -> MON | B5: =IF(B4="","",IF(B4="Lab","Theory",IF(B4="Theory","Lab",""))) -> Theory | C5: =IF(OR(A4="",C4=""),"",100-C4) -> 60 | D5: =IF(COUNTA(A5:C5)=0,"",IF(OR(C5<0,C5>100),"INVALID PERCENT",IF(COUNTIFS($A$2:$A$500,A5,$B$2:$B$500,B5)>1,"DUPLICATE DAY/CLASS","OK"))) -> OK
A6: TUE | B6: Lab | C6: 50 | D6: =IF(COUNTA(A6:C6)=0,"",IF(OR(C6<0,C6>100),"INVALID PERCENT",IF(COUNTIFS($A$2:$A$500,A6,$B$2:$B$500,B6)>1,"DUPLICATE DAY/CLASS","OK"))) -> OK
A7: =IF(OR(A6="",B6=""),"",A6) -> TUE | B7: =IF(B6="","",IF(B6="Lab","Theory",IF(B6="Theory","Lab",""))) -> Theory | C7: =IF(OR(A6="",C6=""),"",100-C6) -> 50 | D7: =IF(COUNTA(A7:C7)=0,"",IF(OR(C7<0,C7>100),"INVALID PERCENT",IF(COUNTIFS($A$2:$A$500,A7,$B$2:$B$500,B7)>1,"DUPLICATE DAY/CLASS","OK"))) -> OK
A8: WED | B8: Lab | C8: 60 | D8: =IF(COUNTA(A8:C8)=0,"",IF(OR(C8<0,C8>100),"INVALID PERCENT",IF(COUNTIFS($A$2:$A$500,A8,$B$2:$B$500,B8)>1,"DUPLICATE DAY/CLASS","OK"))) -> OK
A9: =IF(OR(A8="",B8=""),"",A8) -> WED | B9: =IF(B8="","",IF(B8="Lab","Theory",IF(B8="Theory","Lab",""))) -> Theory | C9: =IF(OR(A8="",C8=""),"",100-C8) -> 40 | D9: =IF(COUNTA(A9:C9)=0,"",IF(OR(C9<0,C9>100),"INVALID PERCENT",IF(COUNTIFS($A$2:$A$500,A9,$B$2:$B$500,B9)>1,"DUPLICATE DAY/CLASS","OK"))) -> OK
A10: THU | B10: Lab | C10: 60 | D10: =IF(COUNTA(A10:C10)=0,"",IF(OR(C10<0,C10>100),"INVALID PERCENT",IF(COUNTIFS($A$2:$A$500,A10,$B$2:$B$500,B10)>1,"DUPLICATE DAY/CLASS","OK"))) -> OK
A11: =IF(OR(A10="",B10=""),"",A10) -> THU | B11: =IF(B10="","",IF(B10="Lab","Theory",IF(B10="Theory","Lab",""))) -> Theory | C11: =IF(OR(A10="",C10=""),"",100-C10) -> 40 | D11: =IF(COUNTA(A11:C11)=0,"",IF(OR(C11<0,C11>100),"INVALID PERCENT",IF(COUNTIFS($A$2:$A$500,A11,$B$2:$B$500,B11)>1,"DUPLICATE DAY/CLASS","OK"))) -> OK
D12: =IF(COUNTA(A12:C12)=0,"",IF(OR(C12<0,C12>100),"INVALID PERCENT",IF(COUNTIFS($A$2:$A$500,A12,$B$2:$B$500,B12)>1,"DUPLICATE DAY/CLASS","OK")))
A13: =IF(OR(A12="",B12=""),"",A12) | B13: =IF(B12="","",IF(B12="Lab","Theory",IF(B12="Theory","Lab",""))) | C13: =IF(OR(A12="",C12=""),"",100-C12) | D13: =IF(COUNTA(A13:C13)=0,"",IF(OR(C13<0,C13>100),"INVALID PERCENT",IF(COUNTIFS($A$2:$A$500,A13,$B$2:$B$500,B13)>1,"DUPLICATE DAY/CLASS","OK"))) -> INVALID PERCENT
D14: =IF(COUNTA(A14:C14)=0,"",IF(OR(C14<0,C14>100),"INVALID PERCENT",IF(COUNTIFS($A$2:$A$500,A14,$B$2:$B$500,B14)>1,"DUPLICATE DAY/CLASS","OK")))
A15: =IF(OR(A14="",B14=""),"",A14) | B15: =IF(B14="","",IF(B14="Lab","Theory",IF(B14="Theory","Lab",""))) | C15: =IF(OR(A14="",C14=""),"",100-C14) | D15: =IF(COUNTA(A15:C15)=0,"",IF(OR(C15<0,C15>100),"INVALID PERCENT",IF(COUNTIFS($A$2:$A$500,A15,$B$2:$B$500,B15)>1,"DUPLICATE DAY/CLASS","OK"))) -> INVALID PERCENT
D16: =IF(COUNTA(A16:C16)=0,"",IF(OR(C16<0,C16>100),"INVALID PERCENT",IF(COUNTIFS($A$2:$A$500,A16,$B$2:$B$500,B16)>1,"DUPLICATE DAY/CLASS","OK")))
A17: =IF(OR(A16="",B16=""),"",A16) | B17: =IF(B16="","",IF(B16="Lab","Theory",IF(B16="Theory","Lab",""))) | C17: =IF(OR(A16="",C16=""),"",100-C16) | D17: =IF(COUNTA(A17:C17)=0,"",IF(OR(C17<0,C17>100),"INVALID PERCENT",IF(COUNTIFS($A$2:$A$500,A17,$B$2:$B$500,B17)>1,"DUPLICATE DAY/CLASS","OK"))) -> INVALID PERCENT
D18: =IF(COUNTA(A18:C18)=0,"",IF(OR(C18<0,C18>100),"INVALID PERCENT",IF(COUNTIFS($A$2:$A$500,A18,$B$2:$B$500,B18)>1,"DUPLICATE DAY/CLASS","OK")))
A19: =IF(OR(A18="",B18=""),"",A18) | B19: =IF(B18="","",IF(B18="Lab","Theory",IF(B18="Theory","Lab",""))) | C19: =IF(OR(A18="",C18=""),"",100-C18) | D19: =IF(COUNTA(A19:C19)=0,"",IF(OR(C19<0,C19>100),"INVALID PERCENT",IF(COUNTIFS($A$2:$A$500,A19,$B$2:$B$500,B19)>1,"DUPLICATE DAY/CLASS","OK"))) -> INVALID PERCENT
D20: =IF(COUNTA(A20:C20)=0,"",IF(OR(C20<0,C20>100),"INVALID PERCENT",IF(COUNTIFS($A$2:$A$500,A20,$B$2:$B$500,B20)>1,"DUPLICATE DAY/CLASS","OK")))
A21: =IF(OR(A20="",B20=""),"",A20) | B21: =IF(B20="","",IF(B20="Lab","Theory",IF(B20="Theory","Lab",""))) | C21: =IF(OR(A20="",C20=""),"",100-C20) | D21: =IF(COUNTA(A21:C21)=0,"",IF(OR(C21<0,C21>100),"INVALID PERCENT",IF(COUNTIFS($A$2:$A$500,A21,$B$2:$B$500,B21)>1,"DUPLICATE DAY/CLASS","OK"))) -> INVALID PERCENT
D22: =IF(COUNTA(A22:C22)=0,"",IF(OR(C22<0,C22>100),"INVALID PERCENT",IF(COUNTIFS($A$2:$A$500,A22,$B$2:$B$500,B22)>1,"DUPLICATE DAY/CLASS","OK")))
A23: =IF(OR(A22="",B22=""),"",A22) | B23: =IF(B22="","",IF(B22="Lab","Theory",IF(B22="Theory","Lab",""))) | C23: =IF(OR(A22="",C22=""),"",100-C22) | D23: =IF(COUNTA(A23:C23)=0,"",IF(OR(C23<0,C23>100),"INVALID PERCENT",IF(COUNTIFS($A$2:$A$500,A23,$B$2:$B$500,B23)>1,"DUPLICATE DAY/CLASS","OK"))) -> INVALID PERCENT
D24: =IF(COUNTA(A24:C24)=0,"",IF(OR(C24<0,C24>100),"INVALID PERCENT",IF(COUNTIFS($A$2:$A$500,A24,$B$2:$B$500,B24)>1,"DUPLICATE DAY/CLASS","OK")))
A25: =IF(OR(A24="",B24=""),"",A24) | B25: =IF(B24="","",IF(B24="Lab","Theory",IF(B24="Theory","Lab",""))) | C25: =IF(OR(A24="",C24=""),"",100-C24) | D25: =IF(COUNTA(A25:C25)=0,"",IF(OR(C25<0,C25>100),"INVALID PERCENT",IF(COUNTIFS($A$2:$A$500,A25,$B$2:$B$500,B25)>1,"DUPLICATE DAY/CLASS","OK"))) -> INVALID PERCENT
D26: =IF(COUNTA(A26:C26)=0,"",IF(OR(C26<0,C26>100),"INVALID PERCENT",IF(COUNTIFS($A$2:$A$500,A26,$B$2:$B$500,B26)>1,"DUPLICATE DAY/CLASS","OK")))
A27: =IF(OR(A26="",B26=""),"",A26) | B27: =IF(B26="","",IF(B26="Lab","Theory",IF(B26="Theory","Lab",""))) | C27: =IF(OR(A26="",C26=""),"",100-C26) | D27: =IF(COUNTA(A27:C27)=0,"",IF(OR(C27<0,C27>100),"INVALID PERCENT",IF(COUNTIFS($A$2:$A$500,A27,$B$2:$B$500,B27)>1,"DUPLICATE DAY/CLASS","OK"))) -> INVALID PERCENT
D28: =IF(COUNTA(A28:C28)=0,"",IF(OR(C28<0,C28>100),"INVALID PERCENT",IF(COUNTIFS($A$2:$A$500,A28,$B$2:$B$500,B28)>1,"DUPLICATE DAY/CLASS","OK")))
A29: =IF(OR(A28="",B28=""),"",A28) | B29: =IF(B28="","",IF(B28="Lab","Theory",IF(B28="Theory","Lab",""))) | C29: =IF(OR(A28="",C28=""),"",100-C28) | D29: =IF(COUNTA(A29:C29)=0,"",IF(OR(C29<0,C29>100),"INVALID PERCENT",IF(COUNTIFS($A$2:$A$500,A29,$B$2:$B$500,B29)>1,"DUPLICATE DAY/CLASS","OK"))) -> INVALID PERCENT
D30: =IF(COUNTA(A30:C30)=0,"",IF(OR(C30<0,C30>100),"INVALID PERCENT",IF(COUNTIFS($A$2:$A$500,A30,$B$2:$B$500,B30)>1,"DUPLICATE DAY/CLASS","OK")))
A31: =IF(OR(A30="",B30=""),"",A30) | B31: =IF(B30="","",IF(B30="Lab","Theory",IF(B30="Theory","Lab",""))) | C31: =IF(OR(A30="",C30=""),"",100-C30) | D31: =IF(COUNTA(A31:C31)=0,"",IF(OR(C31<0,C31>100),"INVALID PERCENT",IF(COUNTIFS($A$2:$A$500,A31,$B$2:$B$500,B31)>1,"DUPLICATE DAY/CLASS","OK"))) -> INVALID PERCENT
D32: =IF(COUNTA(A32:C32)=0,"",IF(OR(C32<0,C32>100),"INVALID PERCENT",IF(COUNTIFS($A$2:$A$500,A32,$B$2:$B$500,B32)>1,"DUPLICATE DAY/CLASS","OK")))
A33: =IF(OR(A32="",B32=""),"",A32) | B33: =IF(B32="","",IF(B32="Lab","Theory",IF(B32="Theory","Lab",""))) | C33: =IF(OR(A32="",C32=""),"",100-C32) | D33: =IF(COUNTA(A33:C33)=0,"",IF(OR(C33<0,C33>100),"INVALID PERCENT",IF(COUNTIFS($A$2:$A$500,A33,$B$2:$B$500,B33)>1,"DUPLICATE DAY/CLASS","OK"))) -> INVALID PERCENT
D34: =IF(COUNTA(A34:C34)=0,"",IF(OR(C34<0,C34>100),"INVALID PERCENT",IF(COUNTIFS($A$2:$A$500,A34,$B$2:$B$500,B34)>1,"DUPLICATE DAY/CLASS","OK")))
A35: =IF(OR(A34="",B34=""),"",A34) | B35: =IF(B34="","",IF(B34="Lab","Theory",IF(B34="Theory","Lab",""))) | C35: =IF(OR(A34="",C34=""),"",100-C34) | D35: =IF(COUNTA(A35:C35)=0,"",IF(OR(C35<0,C35>100),"INVALID PERCENT",IF(COUNTIFS($A$2:$A$500,A35,$B$2:$B$500,B35)>1,"DUPLICATE DAY/CLASS","OK"))) -> INVALID PERCENT
D36: =IF(COUNTA(A36:C36)=0,"",IF(OR(C36<0,C36>100),"INVALID PERCENT",IF(COUNTIFS($A$2:$A$500,A36,$B$2:$B$500,B36)>1,"DUPLICATE DAY/CLASS","OK")))
A37: =IF(OR(A36="",B36=""),"",A36) | B37: =IF(B36="","",IF(B36="Lab","Theory",IF(B36="Theory","Lab",""))) | C37: =IF(OR(A36="",C36=""),"",100-C36) | D37: =IF(COUNTA(A37:C37)=0,"",IF(OR(C37<0,C37>100),"INVALID PERCENT",IF(COUNTIFS($A$2:$A$500,A37,$B$2:$B$500,B37)>1,"DUPLICATE DAY/CLASS","OK"))) -> INVALID PERCENT
D38: =IF(COUNTA(A38:C38)=0,"",IF(OR(C38<0,C38>100),"INVALID PERCENT",IF(COUNTIFS($A$2:$A$500,A38,$B$2:$B$500,B38)>1,"DUPLICATE DAY/CLASS","OK")))
A39: =IF(OR(A38="",B38=""),"",A38) | B39: =IF(B38="","",IF(B38="Lab","Theory",IF(B38="Theory","Lab",""))) | C39: =IF(OR(A38="",C38=""),"",100-C38) | D39: =IF(COUNTA(A39:C39)=0,"",IF(OR(C39<0,C39>100),"INVALID PERCENT",IF(COUNTIFS($A$2:$A$500,A39,$B$2:$B$500,B39)>1,"DUPLICATE DAY/CLASS","OK"))) -> INVALID PERCENT
D40: =IF(COUNTA(A40:C40)=0,"",IF(OR(C40<0,C40>100),"INVALID PERCENT",IF(COUNTIFS($A$2:$A$500,A40,$B$2:$B$500,B40)>1,"DUPLICATE DAY/CLASS","OK")))
...

Sheet Teacher_Unavailability
A1: teacher_abbr * | B1: day * | C1: start_time * | D1: end_time * | E1: status
A2: DMKB | B2: TUE | C2: 0.375 | D2: 0.51388889 | E2: =IF(COUNTA(A2:D2)=0,"",IF(OR(C2="",D2="",C2>=D2),"INVALID TIME RANGE",IF(SUMPRODUCT(($A$2:$A$500=A2)*($B$2:$B$500=B2)*($C$2:$C$500<D2)*($D$2:$D$500>C2))>1,"OVERLAPPING UNAVAILABILITY","OK"))) -> OK
A3: FH | B3: SUN | C3: 0.59027778 | D3: 0.65972222 | E3: =IF(COUNTA(A3:D3)=0,"",IF(OR(C3="",D3="",C3>=D3),"INVALID TIME RANGE",IF(SUMPRODUCT(($A$2:$A$500=A3)*($B$2:$B$500=B3)*($C$2:$C$500<D3)*($D$2:$D$500>C3))>1,"OVERLAPPING UNAVAILABILITY","OK"))) -> OK
E4: =IF(COUNTA(A4:D4)=0,"",IF(OR(C4="",D4="",C4>=D4),"INVALID TIME RANGE",IF(SUMPRODUCT(($A$2:$A$500=A4)*($B$2:$B$500=B4)*($C$2:$C$500<D4)*($D$2:$D$500>C4))>1,"OVERLAPPING UNAVAILABILITY","OK")))
E5: =IF(COUNTA(A5:D5)=0,"",IF(OR(C5="",D5="",C5>=D5),"INVALID TIME RANGE",IF(SUMPRODUCT(($A$2:$A$500=A5)*($B$2:$B$500=B5)*($C$2:$C$500<D5)*($D$2:$D$500>C5))>1,"OVERLAPPING UNAVAILABILITY","OK")))
E6: =IF(COUNTA(A6:D6)=0,"",IF(OR(C6="",D6="",C6>=D6),"INVALID TIME RANGE",IF(SUMPRODUCT(($A$2:$A$500=A6)*($B$2:$B$500=B6)*($C$2:$C$500<D6)*($D$2:$D$500>C6))>1,"OVERLAPPING UNAVAILABILITY","OK")))
E7: =IF(COUNTA(A7:D7)=0,"",IF(OR(C7="",D7="",C7>=D7),"INVALID TIME RANGE",IF(SUMPRODUCT(($A$2:$A$500=A7)*($B$2:$B$500=B7)*($C$2:$C$500<D7)*($D$2:$D$500>C7))>1,"OVERLAPPING UNAVAILABILITY","OK")))
E8: =IF(COUNTA(A8:D8)=0,"",IF(OR(C8="",D8="",C8>=D8),"INVALID TIME RANGE",IF(SUMPRODUCT(($A$2:$A$500=A8)*($B$2:$B$500=B8)*($C$2:$C$500<D8)*($D$2:$D$500>C8))>1,"OVERLAPPING UNAVAILABILITY","OK")))
E9: =IF(COUNTA(A9:D9)=0,"",IF(OR(C9="",D9="",C9>=D9),"INVALID TIME RANGE",IF(SUMPRODUCT(($A$2:$A$500=A9)*($B$2:$B$500=B9)*($C$2:$C$500<D9)*($D$2:$D$500>C9))>1,"OVERLAPPING UNAVAILABILITY","OK")))
E10: =IF(COUNTA(A10:D10)=0,"",IF(OR(C10="",D10="",C10>=D10),"INVALID TIME RANGE",IF(SUMPRODUCT(($A$2:$A$500=A10)*($B$2:$B$500=B10)*($C$2:$C$500<D10)*($D$2:$D$500>C10))>1,"OVERLAPPING UNAVAILABILITY","OK")))
E11: =IF(COUNTA(A11:D11)=0,"",IF(OR(C11="",D11="",C11>=D11),"INVALID TIME RANGE",IF(SUMPRODUCT(($A$2:$A$500=A11)*($B$2:$B$500=B11)*($C$2:$C$500<D11)*($D$2:$D$500>C11))>1,"OVERLAPPING UNAVAILABILITY","OK")))
E12: =IF(COUNTA(A12:D12)=0,"",IF(OR(C12="",D12="",C12>=D12),"INVALID TIME RANGE",IF(SUMPRODUCT(($A$2:$A$500=A12)*($B$2:$B$500=B12)*($C$2:$C$500<D12)*($D$2:$D$500>C12))>1,"OVERLAPPING UNAVAILABILITY","OK")))
E13: =IF(COUNTA(A13:D13)=0,"",IF(OR(C13="",D13="",C13>=D13),"INVALID TIME RANGE",IF(SUMPRODUCT(($A$2:$A$500=A13)*($B$2:$B$500=B13)*($C$2:$C$500<D13)*($D$2:$D$500>C13))>1,"OVERLAPPING UNAVAILABILITY","OK")))
E14: =IF(COUNTA(A14:D14)=0,"",IF(OR(C14="",D14="",C14>=D14),"INVALID TIME RANGE",IF(SUMPRODUCT(($A$2:$A$500=A14)*($B$2:$B$500=B14)*($C$2:$C$500<D14)*($D$2:$D$500>C14))>1,"OVERLAPPING UNAVAILABILITY","OK")))
E15: =IF(COUNTA(A15:D15)=0,"",IF(OR(C15="",D15="",C15>=D15),"INVALID TIME RANGE",IF(SUMPRODUCT(($A$2:$A$500=A15)*($B$2:$B$500=B15)*($C$2:$C$500<D15)*($D$2:$D$500>C15))>1,"OVERLAPPING UNAVAILABILITY","OK")))
... E500: =IF(COUNTA(A500:D500)=0,"",IF(OR(C500="",D500="",C500>=D500),"INVALID TIME RANGE",IF(SUMPRODUCT(($A$2:$A$500=A500)*($B$2:$B$500=B500)*($C$2:$C$500<D500)*($D$2:$D$500>C500))>1,"OVERLAPPING UNAVAILABILITY","OK")))
